Workbook

Sheet README
A1: README
A2: Índice | B2: Información general
A3: Cartera | B3: En esta hoja encuentra Cartera bruta y vencida, leasing y NPL. El NPL Se construye tomando la metodología de construcción de los indicadores gerenciales de la superfinanciera. La cartera vencida contempla el capital en mora mayor a 1 mes en las carteras de consumo y comercial. En la cartera de vivienda, se toma el capital en mora mayor a 4 meses (Fuente: metodología IG y catalogo unico de cuentas SFC.) Para carteras, la fuente son indicadores gerenciales y se toma el total de establecimientos de crèdito sin IOE's (que corresponde a la columna D en el IG). La cartera de vivienda incluye credito y leasing habitacional (puede corroborarse en la fila 69 del IG, en donde se observa el nombre, y es el mismo dato que traemos desde la fila D522 para este archivo). La cartera de consumo incluye credito y leasing de consumo (puede corroborarse en la fila 67 del IG, en donde se observa el nombre, y es el mismo dato que traemos desde la fila D505 para este archivo). La cartera comercial incluye credito y leasing (puede corroborarse en la fila 66 del IG, en donde se observa el nombre, y es el mismo dato que traemos desde la fila D596 para este archivo). Para QRES: se toma la cartera de consumo, comercial y vivienda con titularizaciones. La cartera total que se trabaja y envìa a España corresponde a la suma de estas tres carteras. NO se incluye microcredito en la suma de la total. El archivo cuenta tambièn con los datos de leasing habitacional de bancos y el leasing de compañìas de financiamiento. Estos se obtienen de Datos abiertos. Disclaimer: Es posible que en algún archivo previo de datos de cartera, cómo históricos de algún envío por QRES o a financiera u otro repositorio, se encuentren diferencias en las cifras respecto a las que figuran en este archivo. Esto se explica porque esas cifras provenían de un archivo anterior a este (llamado depositos y cartera), en el que se encontraron errores que fueron corregidos, y cuya corrección llevó a la construcción de este archivo, que es el repositorio oficial. Las diferencias en vivienda se explican por unos cálculos relacionados con leasing y algunas formulas malas que se encontraron en el archivo anterior. Las diferencias en consumo que se pueden encontrar, se deben a que la formula estaba mal hecha y no se traía la cartera de EC sin IOE's sino del total del sector privado (se estaba trayendo la columna E cuando se debía traer la D).
A4: Depósitos | B4: En esta hoja encuentra los depósitos vista, plazo y total, junto con la relación crédito a depósitos. Los depósitos se obtienen de los indicadores gerenciales de la SFC. Los recursos plazo contienen unicamente certificados de depósito a término. Los recursos vista contienen unicamente depositos en cuenta corriente y depositos de ahorro
A5: Titularizaciones | B5: En esta hoja encuentra las titularizaciones por saldo, por tipo y el indicador de calidad. *Indicador de calidad tradicional: Cartera Vencida / Cartera Bruta. La cartera vencida de vivienda en el plazo de 1 a 4 meses sólo incluye las cuotas vencidas. El capital no incluido en la cuotas de 1 a 4 meses se considera vigente.
A6: Profundización financiera | B6: En esta hoja encuentra la relación cartera a PIB. La cartera total en este cálculo incluye microcrédito. PIB tomado de escenariobase; hoja sup, fila 3

Sheet Cartera
D1: Miles de millones de pesos | V1: Variación anual (Porcentaje) | AN1: Variación real (Porcentaje) | BF1: Porcentaje | BN1: Porcentaje | CB1: Porcentaje
B2: Inflación | D2: Cartera comercial y leasing comercial | F2: Cartera consumo y leasing de consumo | H2: Cartera hipotecaria y operaciones de leasing habitacional | J2: Cartera microcrédito y leasing de microcredito | L2: Cartera hipotecaria con titularizaciones | N2: Cartera Total | P2: Cartera total con titularizaciones | R2: Cartera total con titularizaciones sin microcredito | T2: Leasing habitacional de bancos (AI) | U2: Leasing de compañías de financiamiento comercial (FR) | V2: Cartera comercial | X2: Cartera consumo | Z2: Cartera hipotecario | AB2: Cartera microcrédito | AD2: Cartera hipotecaria con titularizaciones | AF2: cartera total | AH2: cartera total con titularizaciones | AJ2: Cartera total con titularizaciones sin microcredito | AL2: Leasing habitacional de bancos (AI) | AM2: Leasing de compañías de financiamiento comercial (FR) | AN2: Cartera comercial | AP2: Cartera consumo | AR2: Cartera hipotecario | AT2: Cartera microcrédito | AV2: Cartera hipotecaria con titularizaciones | AX2: cartera total | AZ2: cartera total con titularizaciones | BB2: cartera total con titularizaciones sin microcredito | BD2: Leasing habitacional de bancos (AI) | BE2: Leasing de compañías de financiamiento comercial (FR) | BF2: Non Performing Loans - NPL | BN2: Participación sobre el total Cartera comercial | BP2: Participación sobre el total Cartera consumo | BR2: Participación sobre el total Cartera hipotecario | BT2: Participación sobre el total Cartera microcrédito | BV2: Participación sobre el total Cartera hipotecaria con titularizaciones | BX2: Participación sobre el total cartera total | BZ2: Participación sobre el total cartera total con titularizaciones | CB2: Contribucion al cambio Cartera comercial | CD2: Contribucion al cambio Cartera consumo | CF2: Contribucion al cambio Cartera hipotecario | CH2: Contribucion al cambio Cartera microcrédito | CJ2: Contribucion al cambio Cartera hipotecaria con titularizaciones | CL2: Contribucion al cambio cartera total | CN2: Contribucion al cambio cartera total con titularizaciones
A3: Fecha | B3: Inflación | C3: IPC | D3: Bruta | E3: Vencida | F3: Bruta | G3: Vencida | H3: Bruta | I3: Vencida | J3: Bruta | K3: Vencida | L3: Bruta | M3: Vencida | N3: Bruta | O3: Vencida | P3: Bruta | Q3: Vencida | R3: Bruta | S3: Vencida | T3: Bruta | U3: Bruta | V3: Bruta | W3: Vencida | X3: Bruta | Y3: Vencida | Z3: Bruta | AA3: Vencida | AB3: Bruta | AC3: Vencida | AD3: Bruta | AE3: Vencida | AF3: Bruta | AG3: Vencida | AH3: Bruta | AI3: Vencida | AJ3: Bruta | AK3: Vencida | AL3: Bruta | AM3: Bruta | AN3: Bruta | AO3: Vencida | AP3: Bruta | AQ3: Vencida | AR3: Bruta | AS3: Vencida | AT3: Bruta | AU3: Vencida | AV3: Bruta | AW3: Vencida | AX3: Bruta | AY3: Vencida | AZ3: Bruta | BA3: Vencida | BB3: Bruta | BC3: Vencida | BD3: Bruta | BE3: Bruta | BF3: Comercial | BG3: Consumo | BH3: Hipotecario | BI3: Microcredito | BJ3: Hipotecario con titularizaciones | BK3: Total | BL3: Total con titularizaciones | BM3: Total con titularizaciones sin microcredito | BN3: Bruta | BO3: Vencida | BP3: Bruta | BQ3: Vencida | BR3: Bruta | BS3: Vencida | BT3: Bruta | BU3: Vencida | BV3: Bruta | BW3: Vencida | BX3: Bruta | BY3: Vencida | BZ3: Bruta | CA3: Vencida | CB3: Bruta | CC3: Vencida | CD3: Bruta | CE3: Vencida | CF3: Bruta | CG3: Vencida | CH3: Bruta | CI3: Vencida | CJ3: Bruta | CK3: Vencida | CL3: Bruta | CM3: Vencida | CN3: Bruta | CO3: Vencida
A4: 34669 | B4: =+'[1]Senda Inflación Total'!F488 -> 22.59 | C4: =+'[1]Senda Inflación Total'!D488 -> 18.25 | D4: 11084.163 | E4: 411.16814 | F4: 5413.4141 | G4: 538.74159 | H4: 5157.5407 | I4: 177.5518 | L4: =+H4 -> 5157.5407 | M4: =+I4 -> 177.5518 | N4: =+D4+F4+H4+J4 -> 21655.117 | O4: =+E4+G4+I4+K4 -> 1127.4615 | P4: =+L4+J4+F4+D4 -> 21655.117 | Q4: =+M4+K4+G4+E4 -> 1127.4615 | R4: =+D4+F4+L4 -> 21655.117 | S4: =+E4+G4+M4 -> 1127.4615 | BF4: =+(E4/D4)*100 -> 3.7095101 | BG4: =+(G4/F4)*100 -> 9.9519744 | BH4: =+(I4/H4)*100 -> 3.4425671 | BJ4: =+(M4/L4)*100 -> 3.4425671 | BK4: =+(O4/N4)*100 -> 5.2064438 | BL4: =+(Q4/P4)*100 -> 5.2064438 | BM4: =+(S4/R4)*100 -> 5.2064438 | BN4: =+(D4/$N4)*100 -> 51.184958 | BO4: =+(E4/$O4)*100 -> 36.468485 | BP4: =+(F4/$N4)*100 -> 24.998313 | BQ4: =+(G4/$O4)*100 -> 47.78359 | BR4: =+(H4/$N4)*100 -> 23.816729 | BS4: =+(I4/$O4)*100 -> 15.747925 | BT4: =+(J4/$N4)*100 -> 0 | BU4: =+(K4/$O4)*100 -> 0 | BV4: ND | BW4: ND | BX4: =+(N4/$N4)*100 -> 100 | BY4: =+(O4/$O4)*100 -> 100 | BZ4: ND | CA4: ND
A5: 34700 | B5: =+'[1]Senda Inflación Total'!F489 -> 21.04 | C5: =+'[1]Senda Inflación Total'!D489 -> 18.59 | D5: 11234.422 | E5: 477.61451 | F5: 5645.6336 | G5: 625.27143 | H5: 5363.6298 | I5: 178.73763 | L5: =+H5 -> 5363.6298 | M5: =+I5 -> 178.73763 | N5: =+D5+F5+H5+J5 -> 22243.685 | O5: =+E5+G5+I5+K5 -> 1281.6236 | P5: =+L5+J5+F5+D5 -> 22243.685 | Q5: =+M5+K5+G5+E5 -> 1281.6236 | R5: =+D5+F5+L5 -> 22243.685 | S5: =+E5+G5+M5 -> 1281.6236 | BF5: =+(E5/D5)*100 -> 4.2513493 | BG5: =+(G5/F5)*100 -> 11.07531 | BH5: =+(I5/H5)*100 -> 3.3324006 | BJ5: =+(M5/L5)*100 -> 3.3324006 | BK5: =+(O5/N5)*100 -> 5.7617412 | BL5: =+(Q5/P5)*100 -> 5.7617412 | BM5: =+(S5/R5)*100 -> 5.7617412 | BN5: =+(D5/$N5)*100 -> 50.506118 | BO5: =+(E5/$O5)*100 -> 37.266364 | BP5: =+(F5/$N5)*100 -> 25.380838 | BQ5: =+(G5/$O5)*100 -> 48.787448 | BR5: =+(H5/$N5)*100 -> 24.113045 | BS5: =+(I5/$O5)*100 -> 13.946188 | BT5: =+(J5/$N5)*100 -> 0 | BU5: =+(K5/$O5)*100 -> 0 | BV5: ND | BW5: ND | BX5: =+(N5/$N5)*100 -> 100 | BY5: =+(O5/$O5)*100 -> 100 | BZ5: ND | CA5: ND
A6: 34731 | B6: =+'[1]Senda Inflación Total'!F490 -> 20.86 | C6: =+'[1]Senda Inflación Total'!D490 -> 19.24 | D6: 11507.894 | E6: 511.89638 | F6: 5714.4183 | G6: 664.79526 | H6: 5523.703 | I6: 188.2036 | L6: =+H6 -> 5523.703 | M6: =+I6 -> 188.2036 | N6: =+D6+F6+H6+J6 -> 22746.015 | O6: =+E6+G6+I6+K6 -> 1364.8952 | P6: =+L6+J6+F6+D6 -> 22746.015 | Q6: =+M6+K6+G6+E6 -> 1364.8952 | R6: =+D6+F6+L6 -> 22746.015 | S6: =+E6+G6+M6 -> 1364.8952 | BF6: =+(E6/D6)*100 -> 4.4482194 | BG6: =+(G6/F6)*100 -> 11.633647 | BH6: =+(I6/H6)*100 -> 3.4071998 | BJ6: =+(M6/L6)*100 -> 3.4071998 | BK6: =+(O6/N6)*100 -> 6.0005905 | BL6: =+(Q6/P6)*100 -> 6.0005905 | BM6: =+(S6/R6)*100 -> 6.0005905 | BN6: =+(D6/$N6)*100 -> 50.593011 | BO6: =+(E6/$O6)*100 -> 37.504445 | BP6: =+(F6/$N6)*100 -> 25.122722 | BQ6: =+(G6/$O6)*100 -> 48.706688 | BR6: =+(H6/$N6)*100 -> 24.284267 | BS6: =+(I6/$O6)*100 -> 13.788868 | BT6: =+(J6/$N6)*100 -> 0 | BU6: =+(K6/$O6)*100 -> 0 | BV6: ND | BW6: ND | BX6: =+(N6/$N6)*100 -> 100 | BY6: =+(O6/$O6)*100 -> 100 | BZ6: ND | CA6: ND
A7: 34759 | B7: =+'[1]Senda Inflación Total'!F491 -> 21.33 | C7: =+'[1]Senda Inflación Total'!D491 -> 19.75 | D7: 12066.986 | E7: 509.42083 | F7: 5828.1441 | G7: 634.7998 | H7: 5725.0241 | I7: 194.02646 | L7: =+H7 -> 5725.0241 | M7: =+I7 -> 194.02646 | N7: =+D7+F7+H7+J7 -> 23620.154 | O7: =+E7+G7+I7+K7 -> 1338.2471 | P7: =+L7+J7+F7+D7 -> 23620.154 | Q7: =+M7+K7+G7+E7 -> 1338.2471 | R7: =+D7+F7+L7 -> 23620.154 | S7: =+E7+G7+M7 -> 1338.2471 | BF7: =+(E7/D7)*100 -> 4.2216078 | BG7: =+(G7/F7)*100 -> 10.891972 | BH7: =+(I7/H7)*100 -> 3.3890942 | BJ7: =+(M7/L7)*100 -> 3.3890942 | BK7: =+(O7/N7)*100 -> 5.6657 | BL7: =+(Q7/P7)*100 -> 5.6657 | BM7: =+(S7/R7)*100 -> 5.6657 | BN7: =+(D7/$N7)*100 -> 51.087669 | BO7: =+(E7/$O7)*100 -> 38.066276 | BP7: =+(F7/$N7)*100 -> 24.674454 | BQ7: =+(G7/$O7)*100 -> 47.435171 | BR7: =+(H7/$N7)*100 -> 24.237877 | BS7: =+(I7/$O7)*100 -> 14.498553 | BT7: =+(J7/$N7)*100 -> 0 | BU7: =+(K7/$O7)*100 -> 0 | BV7: ND | BW7: ND | BX7: =+(N7/$N7)*100 -> 100 | BY7: =+(O7/$O7)*100 -> 100 | BZ7: ND | CA7: ND
A8: 34790 | B8: =+'[1]Senda Inflación Total'!F492 -> 21.17 | C8: =+'[1]Senda Inflación Total'!D492 -> 20.19 | D8: 12371.751 | E8: 531.89046 | F8: 5970.7464 | G8: 704.00344 | H8: 5877.3538 | I8: 205.80512 | L8: =+H8 -> 5877.3538 | M8: =+I8 -> 205.80512 | N8: =+D8+F8+H8+J8 -> 24219.851 | O8: =+E8+G8+I8+K8 -> 1441.699 | P8: =+L8+J8+F8+D8 -> 24219.851 | Q8: =+M8+K8+G8+E8 -> 1441.699 | R8: =+D8+F8+L8 -> 24219.851 | S8: =+E8+G8+M8 -> 1441.699 | BF8: =+(E8/D8)*100 -> 4.2992336 | BG8: =+(G8/F8)*100 -> 11.790878 | BH8: =+(I8/H8)*100 -> 3.5016629 | BJ8: =+(M8/L8)*100 -> 3.5016629 | BK8: =+(O8/N8)*100 -> 5.9525512 | BL8: =+(Q8/P8)*100 -> 5.9525512 | BM8: =+(S8/R8)*100 -> 5.9525512 | BN8: =+(D8/$N8)*100 -> 51.081036 | BO8: =+(E8/$O8)*100 -> 36.893308 | BP8: =+(F8/$N8)*100 -> 24.652284 | BQ8: =+(G8/$O8)*100 -> 48.831513 | BR8: =+(H8/$N8)*100 -> 24.26668 | BS8: =+(I8/$O8)*100 -> 14.275179 | BT8: =+(J8/$N8)*100 -> 0 | BU8: =+(K8/$O8)*100 -> 0 | BV8: ND | BW8: ND | BX8: =+(N8/$N8)*100 -> 100 | BY8: =+(O8/$O8)*100 -> 100 | BZ8: ND | CA8: ND
A9: 34820 | B9: =+'[1]Senda Inflación Total'!F493 -> 21.3 | C9: =+'[1]Senda Inflación Total'!D493 -> 20.52 | D9: 12803.208 | E9: 533.74045 | F9: 6077.1305 | G9: 722.78708 | H9: 6057.1458 | I9: 199.86292 | L9: =+H9 -> 6057.1458 | M9: =+I9 -> 199.86292 | N9: =+D9+F9+H9+J9 -> 24937.485 | O9: =+E9+G9+I9+K9 -> 1456.3905 | P9: =+L9+J9+F9+D9 -> 24937.485 | Q9: =+M9+K9+G9+E9 -> 1456.3905 | R9: =+D9+F9+L9 -> 24937.485 | S9: =+E9+G9+M9 -> 1456.3905 | BF9: =+(E9/D9)*100 -> 4.1688023 | BG9: =+(G9/F9)*100 -> 11.893559 | BH9: =+(I9/H9)*100 -> 3.2996221 | BJ9: =+(M9/L9)*100 -> 3.2996221 | BK9: =+(O9/N9)*100 -> 5.8401658 | BL9: =+(Q9/P9)*100 -> 5.8401658 | BM9: =+(S9/R9)*100 -> 5.8401658 | BN9: =+(D9/$N9)*100 -> 51.341218 | BO9: =+(E9/$O9)*100 -> 36.64817 | BP9: =+(F9/$N9)*100 -> 24.369461 | BQ9: =+(G9/$O9)*100 -> 49.628661 | BR9: =+(H9/$N9)*100 -> 24.289321 | BS9: =+(I9/$O9)*100 -> 13.723169 | BT9: =+(J9/$N9)*100 -> 0 | BU9: =+(K9/$O9)*100 -> 0 | BV9: ND | BW9: ND | BX9: =+(N9/$N9)*100 -> 100 | BY9: =+(O9/$O9)*100 -> 100 | BZ9: ND | CA9: ND
A10: 34851 | B10: =+'[1]Senda Inflación Total'!F494 -> 21.66 | C10: =+'[1]Senda Inflación Total'!D494 -> 20.77 | D10: 13231.281 | E10: 529.12972 | F10: 6141.0301 | G10: 699.14152 | H10: 6230.9789 | I10: 217.34537 | L10: =+H10 -> 6230.9789 | M10: =+I10 -> 217.34537 | N10: =+D10+F10+H10+J10 -> 25603.29 | O10: =+E10+G10+I10+K10 -> 1445.6166 | P10: =+L10+J10+F10+D10 -> 25603.29 | Q10: =+M10+K10+G10+E10 -> 1445.6166 | R10: =+D10+F10+L10 -> 25603.29 | S10: =+E10+G10+M10 -> 1445.6166 | BF10: =+(E10/D10)*100 -> 3.9990817 | BG10: =+(G10/F10)*100 -> 11.38476 | BH10: =+(I10/H10)*100 -> 3.4881416 | BI10: =+(K10/J10)*100 -> #DIV/0! | BJ10: =+(M10/L10)*100 -> 3.4881416 | BK10: =+(O10/N10)*100 -> 5.6462144 | BL10: =+(Q10/P10)*100 -> 5.6462144 | BM10: =+(S10/R10)*100 -> 5.6462144 | BN10: =+(D10/$N10)*100 -> 51.678049 | BO10: =+(E10/$O10)*100 -> 36.602355 | BP10: =+(F10/$N10)*100 -> 23.985317 | BQ10: =+(G10/$O10)*100 -> 48.362859 | BR10: =+(H10/$N10)*100 -> 24.336634 | BS10: =+(I10/$O10)*100 -> 15.034786 | BT10: =+(J10/$N10)*100 -> 0 | BU10: =+(K10/$O10)*100 -> 0 | BV10: ND | BW10: ND | BX10: =+(N10/$N10)*100 -> 100 | BY10: =+(O10/$O10)*100 -> 100 | BZ10: ND | CA10: ND
A11: 34881 | B11: =+'[1]Senda Inflación Total'!F495 -> 21.5 | C11: =+'[1]Senda Inflación Total'!D495 -> 20.93 | D11: 13740.455 | E11: 641.29952 | F11: 6227.5415 | G11: 780.72466 | H11: 6271.7224 | I11: 212.57915 | L11: =+H11 -> 6271.7224 | M11: =+I11 -> 212.57915 | N11: =+D11+F11+H11+J11 -> 26239.719 | O11: =+E11+G11+I11+K11 -> 1634.6033 | P11: =+L11+J11+F11+D11 -> 26239.719 | Q11: =+M11+K11+G11+E11 -> 1634.6033 | R11: =+D11+F11+L11 -> 26239.719 | S11: =+E11+G11+M11 -> 1634.6033 | BF11: =+(E11/D11)*100 -> 4.6672365 | BG11: =+(G11/F11)*100 -> 12.536643 | BH11: =+(I11/H11)*100 -> 3.3894859 | BI11: =+(K11/J11)*100 -> #DIV/0! | BJ11: =+(M11/L11)*100 -> 3.3894859 | BK11: =+(O11/N11)*100 -> 6.2295002 | BL11: =+(Q11/P11)*100 -> 6.2295002 | BM11: =+(S11/R11)*100 -> 6.2295002 | BN11: =+(D11/$N11)*100 -> 52.365099 | BO11: =+(E11/$O11)*100 -> 39.232731 | BP11: =+(F11/$N11)*100 -> 23.733263 | BQ11: =+(G11/$O11)*100 -> 47.762331 | BR11: =+(H11/$N11)*100 -> 23.901638 | BS11: =+(I11/$O11)*100 -> 13.004938 | BT11: =+(J11/$N11)*100 -> 0 | BU11: =+(K11/$O11)*100 -> 0 | BV11: ND | BW11: ND | BX11: =+(N11/$N11)*100 -> 100 | BY11: =+(O11/$O11)*100 -> 100 | BZ11: ND | CA11: ND
A12: 34912 | B12: =+'[1]Senda Inflación Total'!F496 -> 21.09 | C12: =+'[1]Senda Inflación Total'!D496 -> 21.07 | D12: 14246.975 | E12: 662.50681 | F12: 6325.7462 | G12: 785.93739 | H12: 6496.9663 | I12: 224.67818 | L12: =+H12 -> 6496.9663 | M12: =+I12 -> 224.67818 | N12: =+D12+F12+H12+J12 -> 27069.687 | O12: =+E12+G12+I12+K12 -> 1673.1224 | P12: =+L12+J12+F12+D12 -> 27069.687 | Q12: =+M12+K12+G12+E12 -> 1673.1224 | R12: =+D12+F12+L12 -> 27069.687 | S12: =+E12+G12+M12 -> 1673.1224 | BF12: =+(E12/D12)*100 -> 4.6501578 | BG12: =+(G12/F12)*100 -> 12.424422 | BH12: =+(I12/H12)*100 -> 3.4582014 | BI12: =+(K12/J12)*100 -> #DIV/0! | BJ12: =+(M12/L12)*100 -> 3.4582014 | BK12: =+(O12/N12)*100 -> 6.1807969 | BL12: =+(Q12/P12)*100 -> 6.1807969 | BM12: =+(S12/R12)*100 -> 6.1807969 | BN12: =+(D12/$N12)*100 -> 52.630733 | BO12: =+(E12/$O12)*100 -> 39.597032 | BP12: =+(F12/$N12)*100 -> 23.368376 | BQ12: =+(G12/$O12)*100 -> 46.974292 | BR12: =+(H12/$N12)*100 -> 24.000892 | BS12: =+(I12/$O12)*100 -> 13.428676 | BT12: =+(J12/$N12)*100 -> 0 | BU12: =+(K12/$O12)*100 -> 0 | BV12: ND | BW12: ND | BX12: =+(N12/$N12)*100 -> 100 | BY12: =+(O12/$O12)*100 -> 100 | BZ12: ND | CA12: ND
A13: 34943 | B13: =+'[1]Senda Inflación Total'!F497 -> 20.79 | C13: =+'[1]Senda Inflación Total'!D497 -> 21.24 | D13: 14763.526 | E13: 649.97139 | F13: 6472.4305 | G13: 779.23711 | H13: 6687.4221 | I13: 227.71376 | L13: =+H13 -> 6687.4221 | M13: =+I13 -> 227.71376 | N13: =+D13+F13+H13+J13 -> 27923.379 | O13: =+E13+G13+I13+K13 -> 1656.9223 | P13: =+L13+J13+F13+D13 -> 27923.379 | Q13: =+M13+K13+G13+E13 -> 1656.9223 | R13: =+D13+F13+L13 -> 27923.379 | S13: =+E13+G13+M13 -> 1656.9223 | BF13: =+(E13/D13)*100 -> 4.4025483 | BG13: =+(G13/F13)*100 -> 12.039328 | BH13: =+(I13/H13)*100 -> 3.4051052 | BI13: =+(K13/J13)*100 -> #DIV/0! | BJ13: =+(M13/L13)*100 -> 3.4051052 | BK13: =+(O13/N13)*100 -> 5.9338172 | BL13: =+(Q13/P13)*100 -> 5.9338172 | BM13: =+(S13/R13)*100 -> 5.9338172 | BN13: =+(D13/$N13)*100 -> 52.871561 | BO13: =+(E13/$O13)*100 -> 39.227633 | BP13: =+(F13/$N13)*100 -> 23.179252 | BQ13: =+(G13/$O13)*100 -> 47.02919 | BR13: =+(H13/$N13)*100 -> 23.949186 | BS13: =+(I13/$O13)*100 -> 13.743177 | BT13: =+(J13/$N13)*100 -> 0 | BU13: =+(K13/$O13)*100 -> 0 | BV13: ND | BW13: ND | BX13: =+(N13/$N13)*100 -> 100 | BY13: =+(O13/$O13)*100 -> 100 | BZ13: ND | CA13: ND
A14: 34973 | B14: =+'[1]Senda Inflación Total'!F498 -> 20.52 | C14: =+'[1]Senda Inflación Total'!D498 -> 21.43 | D14: 15161.709 | E14: 703.51071 | F14: 6591.4236 | G14: 797.70905 | H14: 6895.5346 | I14: 236.63223 | L14: =+H14 -> 6895.5346 | M14: =+I14 -> 236.63223 | N14: =+D14+F14+H14+J14 -> 28648.667 | O14: =+E14+G14+I14+K14 -> 1737.852 | P14: =+L14+J14+F14+D14 -> 28648.667 | Q14: =+M14+K14+G14+E14 -> 1737.852 | R14: =+D14+F14+L14 -> 28648.667 | S14: =+E14+G14+M14 -> 1737.852 | BF14: =+(E14/D14)*100 -> 4.6400489 | BG14: =+(G14/F14)*100 -> 12.102227 | BH14: =+(I14/H14)*100 -> 3.4316735 | BI14: =+(K14/J14)*100 -> #DIV/0! | BJ14: =+(M14/L14)*100 -> 3.4316735 | BK14: =+(O14/N14)*100 -> 6.0660832 | BL14: =+(Q14/P14)*100 -> 6.0660832 | BM14: =+(S14/R14)*100 -> 6.0660832 | BN14: =+(D14/$N14)*100 -> 52.922912 | BO14: =+(E14/$O14)*100 -> 40.481624 | BP14: =+(F14/$N14)*100 -> 23.007785 | BQ14: =+(G14/$O14)*100 -> 45.902013 | BR14: =+(H14/$N14)*100 -> 24.069303 | BS14: =+(I14/$O14)*100 -> 13.616363 | BT14: =+(J14/$N14)*100 -> 0 | BU14: =+(K14/$O14)*100 -> 0 | BV14: ND | BW14: ND | BX14: =+(N14/$N14)*100 -> 100 | BY14: =+(O14/$O14)*100 -> 100 | BZ14: ND | CA14: ND
A15: 35004 | B15: =+'[1]Senda Inflación Total'!F499 -> 20.13 | C15: =+'[1]Senda Inflación Total'!D499 -> 21.6 | D15: 15643.495 | E15: 725.00084 | F15: 6690.6695 | G15: 828.64086 | H15: 7049.7487 | I15: 250.81978 | L15: =+H15 -> 7049.7487 | M15: =+I15 -> 250.81978 | N15: =+D15+F15+H15+J15 -> 29383.913 | O15: =+E15+G15+I15+K15 -> 1804.4615 | P15: =+L15+J15+F15+D15 -> 29383.913 | Q15: =+M15+K15+G15+E15 -> 1804.4615 | R15: =+D15+F15+L15 -> 29383.913 | S15: =+E15+G15+M15 -> 1804.4615 | BF15: =+(E15/D15)*100 -> 4.6345197 | BG15: =+(G15/F15)*100 -> 12.385022 | BH15: =+(I15/H15)*100 -> 3.5578542 | BI15: =+(K15/J15)*100 -> #DIV/0! | BJ15: =+(M15/L15)*100 -> 3.5578542 | BK15: =+(O15/N15)*100 -> 6.1409843 | BL15: =+(Q15/P15)*100 -> 6.1409843 | BM15: =+(S15/R15)*100 -> 6.1409843 | BN15: =+(D15/$N15)*100 -> 53.238297 | BO15: =+(E15/$O15)*100 -> 40.178239 | BP15: =+(F15/$N15)*100 -> 22.769838 | BQ15: =+(G15/$O15)*100 -> 45.921782 | BR15: =+(H15/$N15)*100 -> 23.991865 | BS15: =+(I15/$O15)*100 -> 13.89998 | BT15: =+(J15/$N15)*100 -> 0 | BU15: =+(K15/$O15)*100 -> 0 | BV15: ND | BW15: ND | BX15: =+(N15/$N15)*100 -> 100 | BY15: =+(O15/$O15)*100 -> 100 | BZ15: ND | CA15: ND
A16: 35034 | B16: =+'[1]Senda Inflación Total'!F500 -> 19.46 | C16: =+'[1]Senda Inflación Total'!D500 -> 21.8 | D16: 16081.66 | E16: 656.73166 | F16: 6735.1318 | G16: 821.23487 | H16: 7265.1811 | I16: 251.12442 | L16: =+H16 -> 7265.1811 | M16: =+I16 -> 251.12442 | N16: =+D16+F16+H16+J16 -> 30081.972 | O16: =+E16+G16+I16+K16 -> 1729.0909 | P16: =+L16+J16+F16+D16 -> 30081.972 | Q16: =+M16+K16+G16+E16 -> 1729.0909 | R16: =+D16+F16+L16 -> 30081.972 | S16: =+E16+G16+M16 -> 1729.0909 | V16: =+D16/D4*100-100 -> 45.086823 | W16: =+E16/E4*100-100 -> 59.723382 | X16: =+F16/F4*100-100 -> 24.415603 | Y16: =+G16/G4*100-100 -> 52.435766 | Z16: =+H16/H4*100-100 -> 40.865221 | AA16: =+I16/I4*100-100 -> 41.437271 | AD16: =+L16/L4*100-100 -> 40.865221 | AE16: =+M16/M4*100-100 -> 41.437271 | AF16: =+N16/N4*100-100 -> 38.913919 | AG16: =+O16/O4*100-100 -> 53.361414 | AH16: =+P16/P4*100-100 -> 38.913919 | AI16: =+Q16/Q4*100-100 -> 53.361414 | AJ16: =+R16/R4*100-100 -> 38.913919 | AK16: =+S16/S4*100-100 -> 53.361414 | AN16: =+(1+V16/100)/(1+$B16/100)*100-100 -> 21.452221 | AO16: =+(1+W16/100)/(1+$B16/100)*100-100 -> 33.704489 | AP16: =+(1+X16/100)/(1+$B16/100)*100-100 -> 4.1483366 | AQ16: =+(1+Y16/100)/(1+$B16/100)*100-100 -> 27.604023 | AR16: =+(1+Z16/100)/(1+$B16/100)*100-100 -> 17.918317 | AS16: =+(1+AA16/100)/(1+$B16/100)*100-100 -> 18.39718 | AT16: =+(1+AB16/100)/(1+$B16/100)*100-100 -> -16.289972 | AU16: =+(1+AC16/100)/(1+$B16/100)*100-100 -> -16.289972 | ... BC16: =+(1+AK16/100)/(1+$B16/100)*100-100 -> 28.378884 | BF16: =+(E16/D16)*100 -> 4.0837307 | BG16: =+(G16/F16)*100 -> 12.193301 | BH16: =+(I16/H16)*100 -> 3.4565473 | BI16: =+(K16/J16)*100 -> #DIV/0! | BJ16: =+(M16/L16)*100 -> 3.4565473 | BK16: =+(O16/N16)*100 -> 5.7479308 | BL16: =+(Q16/P16)*100 -> 5.7479308 | BM16: =+(S16/R16)*100 -> 5.7479308 | BN16: =+(D16/$N16)*100 -> 53.459458 | BO16: =+(E16/$O16)*100 -> 37.981325 | BP16: =+(F16/$N16)*100 -> 22.389263 | BQ16: =+(G16/$O16)*100 -> 47.495181 | BR16: =+(H16/$N16)*100 -> 24.151279 | BS16: =+(I16/$O16)*100 -> 14.523494 | BT16: =+(J16/$N16)*100 -> 0 | BU16: =+(K16/$O16)*100 -> 0 | BV16: ND | BW16: ND | BX16: =+(N16/$N16)*100 -> 100 | BY16: =+(O16/$O16)*100 -> 100 | BZ16: ND | CA16: ND
A17: 35065 | B17: =+'[1]Senda Inflación Total'!F501 -> 20.24 | C17: =+'[1]Senda Inflación Total'!D501 -> 22.35 | D17: 16370.864 | E17: 759.31188 | F17: 6892.3545 | G17: 883.74904 | H17: 7469.316 | I17: 276.49345 | L17: =+H17 -> 7469.316 | M17: =+I17 -> 276.49345 | N17: =+D17+F17+H17+J17 -> 30732.535 | O17: =+E17+G17+I17+K17 -> 1919.5544 | P17: =+L17+J17+F17+D17 -> 30732.535 | Q17: =+M17+K17+G17+E17 -> 1919.5544 | R17: =+D17+F17+L17 -> 30732.535 | S17: =+E17+G17+M17 -> 1919.5544 | V17: =+D17/D5*100-100 -> 45.720575 | W17: =+E17/E5*100-100 -> 58.98007 | X17: =+F17/F5*100-100 -> 22.082923 | Y17: =+G17/G5*100-100 -> 41.338465 | Z17: =+H17/H5*100-100 -> 39.258606 | AA17: =+I17/I5*100-100 -> 54.692355 | AD17: =+L17/L5*100-100 -> 39.258606 | AE17: =+M17/M5*100-100 -> 54.692355 | AF17: =+N17/N5*100-100 -> 38.162964 | AG17: =+O17/O5*100-100 -> 49.775208 | AH17: =+P17/P5*100-100 -> 38.162964 | AI17: =+Q17/Q5*100-100 -> 49.775208 | AJ17: =+R17/R5*100-100 -> 38.162964 | AK17: =+S17/S5*100-100 -> 49.775208 | AN17: =+(1+V17/100)/(1+$B17/100)*100-100 -> 21.19143 | AO17: =+(1+W17/100)/(1+$B17/100)*100-100 -> 32.218953 | AP17: =+(1+X17/100)/(1+$B17/100)*100-100 -> 1.5327041 | AQ17: =+(1+Y17/100)/(1+$B17/100)*100-100 -> 17.54696 | AR17: =+(1+Z17/100)/(1+$B17/100)*100-100 -> 15.817204 | AS17: =+(1+AA17/100)/(1+$B17/100)*100-100 -> 28.65299 | AT17: =+(1+AB17/100)/(1+$B17/100)*100-100 -> -16.833001 | AU17: =+(1+AC17/100)/(1+$B17/100)*100-100 -> -16.833001 | ... BC17: =+(1+AK17/100)/(1+$B17/100)*100-100 -> 24.563546 | BF17: =+(E17/D17)*100 -> 4.6381906 | BG17: =+(G17/F17)*100 -> 12.822165 | BH17: =+(I17/H17)*100 -> 3.7017238 | BI17: =+(K17/J17)*100 -> #DIV/0! | BJ17: =+(M17/L17)*100 -> 3.7017238 | BK17: =+(O17/N17)*100 -> 6.2460008 | BL17: =+(Q17/P17)*100 -> 6.2460008 | BM17: =+(S17/R17)*100 -> 6.2460008 | BN17: =+(D17/$N17)*100 -> 53.268838 | BO17: =+(E17/$O17)*100 -> 39.556675 | BP17: =+(F17/$N17)*100 -> 22.426899 | BQ17: =+(G17/$O17)*100 -> 46.039282 | BR17: =+(H17/$N17)*100 -> 24.304263 | BS17: =+(I17/$O17)*100 -> 14.404044 | BT17: =+(J17/$N17)*100 -> 0 | BU17: =+(K17/$O17)*100 -> 0 | BV17: ND | BW17: ND | BX17: =+(N17/$N17)*100 -> 100 | BY17: =+(O17/$O17)*100 -> 100 | BZ17: ND | CA17: ND
A18: 35096 | B18: =+'[1]Senda Inflación Total'!F502 -> 20.81 | C18: =+'[1]Senda Inflación Total'!D502 -> 23.25 | D18: 16628.831 | E18: 806.2291 | F18: 6983.8367 | G18: 929.75646 | H18: 7650.069 | I18: 282.94512 | L18: =+H18 -> 7650.069 | M18: =+I18 -> 282.94512 | N18: =+D18+F18+H18+J18 -> 31262.737 | O18: =+E18+G18+I18+K18 -> 2018.9307 | P18: =+L18+J18+F18+D18 -> 31262.737 | Q18: =+M18+K18+G18+E18 -> 2018.9307 | R18: =+D18+F18+L18 -> 31262.737 | S18: =+E18+G18+M18 -> 2018.9307 | V18: =+D18/D6*100-100 -> 44.499343 | W18: =+E18/E6*100-100 -> 57.498496 | X18: =+F18/F6*100-100 -> 22.214308 | Y18: =+G18/G6*100-100 -> 39.85606 | Z18: =+H18/H6*100-100 -> 38.495299 | AA18: =+I18/I6*100-100 -> 50.339908 | AD18: =+L18/L6*100-100 -> 38.495299 | AE18: =+M18/M6*100-100 -> 50.339908 | AF18: =+N18/N6*100-100 -> 37.442697 | AG18: =+O18/O6*100-100 -> 47.918362 | AH18: =+P18/P6*100-100 -> 37.442697 | AI18: =+Q18/Q6*100-100 -> 47.918362 | AJ18: =+R18/R6*100-100 -> 37.442697 | AK18: =+S18/S6*100-100 -> 47.918362 | AN18: =+(1+V18/100)/(1+$B18/100)*100-100 -> 19.60876 | AO18: =+(1+W18/100)/(1+$B18/100)*100-100 -> 30.368758 | AP18: =+(1+X18/100)/(1+$B18/100)*100-100 -> 1.1624105 | AQ18: =+(1+Y18/100)/(1+$B18/100)*100-100 -> 15.765301 | AR18: =+(1+Z18/100)/(1+$B18/100)*100-100 -> 14.638936 | AS18: =+(1+AA18/100)/(1+$B18/100)*100-100 -> 24.443265 | AT18: =+(1+AB18/100)/(1+$B18/100)*100-100 -> -17.225395 | AU18: =+(1+AC18/100)/(1+$B18/100)*100-100 -> -17.225395 | ... BC18: =+(1+AK18/100)/(1+$B18/100)*100-100 -> 22.438839 | BF18: =+(E18/D18)*100 -> 4.848381 | BG18: =+(G18/F18)*100 -> 13.312975 | BH18: =+(I18/H18)*100 -> 3.6985957 | BI18: =+(K18/J18)*100 -> #DIV/0! | BJ18: =+(M18/L18)*100 -> 3.6985957 | BK18: =+(O18/N18)*100 -> 6.457946 | BL18: =+(Q18/P18)*100 -> 6.457946 | BM18: =+(S18/R18)*100 -> 6.457946 | BN18: =+(D18/$N18)*100 -> 53.190581 | BO18: =+(E18/$O18)*100 -> 39.933471 | BP18: =+(F18/$N18)*100 -> 22.339172 | BQ18: =+(G18/$O18)*100 -> 46.051926 | BR18: =+(H18/$N18)*100 -> 24.470247 | BS18: =+(I18/$O18)*100 -> 14.014603 | BT18: =+(J18/$N18)*100 -> 0 | BU18: =+(K18/$O18)*100 -> 0 | BV18: ND | BW18: ND | BX18: =+(N18/$N18)*100 -> 100 | BY18: =+(O18/$O18)*100 -> 100 | BZ18: ND | CA18: ND
A19: 35125 | B19: =+'[1]Senda Inflación Total'!F503 -> 20.2 | C19: =+'[1]Senda Inflación Total'!D503 -> 23.74 | D19: 17066.408 | E19: 809.17202 | F19: 7068.8792 | G19: 946.91955 | H19: 7854.8238 | I19: 292.03142 | L19: =+H19 -> 7854.8238 | M19: =+I19 -> 292.03142 | N19: =+D19+F19+H19+J19 -> 31990.111 | O19: =+E19+G19+I19+K19 -> 2048.123 | P19: =+L19+J19+F19+D19 -> 31990.111 | Q19: =+M19+K19+G19+E19 -> 2048.123 | R19: =+D19+F19+L19 -> 31990.111 | S19: =+E19+G19+M19 -> 2048.123 | V19: =+D19/D7*100-100 -> 41.430573 | W19: =+E19/E7*100-100 -> 58.841565 | X19: =+F19/F7*100-100 -> 21.288681 | Y19: =+G19/G7*100-100 -> 49.168218 | Z19: =+H19/H7*100-100 -> 37.201585 | AA19: =+I19/I7*100-100 -> 50.511131 | AD19: =+L19/L7*100-100 -> 37.201585 | AE19: =+M19/M7*100-100 -> 50.511131 | AF19: =+N19/N7*100-100 -> 35.435654 | AG19: =+O19/O7*100-100 -> 53.045204 | AH19: =+P19/P7*100-100 -> 35.435654 | AI19: =+Q19/Q7*100-100 -> 53.045204 | AJ19: =+R19/R7*100-100 -> 35.435654 | AK19: =+S19/S7*100-100 -> 53.045204 | AN19: =+(1+V19/100)/(1+$B19/100)*100-100 -> 17.662706 | AO19: =+(1+W19/100)/(1+$B19/100)*100-100 -> 32.147725 | AP19: =+(1+X19/100)/(1+$B19/100)*100-100 -> 0.90572457 | AQ19: =+(1+Y19/100)/(1+$B19/100)*100-100 -> 24.100015 | AR19: =+(1+Z19/100)/(1+$B19/100)*100-100 -> 14.144414 | AS19: =+(1+AA19/100)/(1+$B19/100)*100-100 -> 25.217247 | AT19: =+(1+AB19/100)/(1+$B19/100)*100-100 -> -16.805324 | AU19: =+(1+AC19/100)/(1+$B19/100)*100-100 -> -16.805324 | ... BC19: =+(1+AK19/100)/(1+$B19/100)*100-100 -> 27.325461 | BF19: =+(E19/D19)*100 -> 4.7413142 | BG19: =+(G19/F19)*100 -> 13.395611 | BH19: =+(I19/H19)*100 -> 3.7178609 | BI19: =+(K19/J19)*100 -> #DIV/0! | BJ19: =+(M19/L19)*100 -> 3.7178609 | BK19: =+(O19/N19)*100 -> 6.4023629 | BL19: =+(Q19/P19)*100 -> 6.4023629 | BM19: =+(S19/R19)*100 -> 6.4023629 | BN19: =+(D19/$N19)*100 -> 53.349011 | BO19: =+(E19/$O19)*100 -> 39.50798 | BP19: =+(F19/$N19)*100 -> 22.097076 | BQ19: =+(G19/$O19)*100 -> 46.23353 | BR19: =+(H19/$N19)*100 -> 24.553912 | BS19: =+(I19/$O19)*100 -> 14.25849 | BT19: =+(J19/$N19)*100 -> 0 | BU19: =+(K19/$O19)*100 -> 0 | BV19: ND | BW19: ND | BX19: =+(N19/$N19)*100 -> 100 | BY19: =+(O19/$O19)*100 -> 100 | BZ19: ND | CA19: ND
A20: 35156 | B20: =+'[1]Senda Inflación Total'!F504 -> 19.9 | C20: =+'[1]Senda Inflación Total'!D504 -> 24.21 | D20: 17302 | E20: 895.77896 | F20: 7166.5109 | G20: 994.33781 | H20: 8027.5465 | I20: 307.19289 | L20: =+H20 -> 8027.5465 | M20: =+I20 -> 307.19289 | N20: =+D20+F20+H20+J20 -> 32496.057 | O20: =+E20+G20+I20+K20 -> 2197.3097 | P20: =+L20+J20+F20+D20 -> 32496.057 | Q20: =+M20+K20+G20+E20 -> 2197.3097 | R20: =+D20+F20+L20 -> 32496.057 | S20: =+E20+G20+M20 -> 2197.3097 | V20: =+D20/D8*100-100 -> 39.850863 | W20: =+E20/E8*100-100 -> 68.414181 | X20: =+F20/F8*100-100 -> 20.027054 | Y20: =+G20/G8*100-100 -> 41.240476 | Z20: =+H20/H8*100-100 -> 36.584368 | AA20: =+I20/I8*100-100 -> 49.263969 | AD20: =+L20/L8*100-100 -> 36.584368 | AE20: =+M20/M8*100-100 -> 49.263969 | AF20: =+N20/N8*100-100 -> 34.171171 | AG20: =+O20/O8*100-100 -> 52.411123 | AH20: =+P20/P8*100-100 -> 34.171171 | AI20: =+Q20/Q8*100-100 -> 52.411123 | AJ20: =+R20/R8*100-100 -> 34.171171 | AK20: =+S20/S8*100-100 -> 52.411123 | AN20: =+(1+V20/100)/(1+$B20/100)*100-100 -> 16.639585 | AO20: =+(1+W20/100)/(1+$B20/100)*100-100 -> 40.462202 | AP20: =+(1+X20/100)/(1+$B20/100)*100-100 -> 0.10596622 | AQ20: =+(1+Y20/100)/(1+$B20/100)*100-100 -> 17.798562 | AR20: =+(1+Z20/100)/(1+$B20/100)*100-100 -> 13.915236 | AS20: =+(1+AA20/100)/(1+$B20/100)*100-100 -> 24.490383 | AT20: =+(1+AB20/100)/(1+$B20/100)*100-100 -> -16.597164 | AU20: =+(1+AC20/100)/(1+$B20/100)*100-100 -> -16.597164 | ... BC20: =+(1+AK20/100)/(1+$B20/100)*100-100 -> 27.115198 | BF20: =+(E20/D20)*100 -> 5.1773145 | BG20: =+(G20/F20)*100 -> 13.874783 | BH20: =+(I20/H20)*100 -> 3.8267345 | BI20: =+(K20/J20)*100 -> #DIV/0! | BJ20: =+(M20/L20)*100 -> 3.8267345 | BK20: =+(O20/N20)*100 -> 6.7617731 | BL20: =+(Q20/P20)*100 -> 6.7617731 | BM20: =+(S20/R20)*100 -> 6.7617731 | BN20: =+(D20/$N20)*100 -> 53.243382 | BO20: =+(E20/$O20)*100 -> 40.767079 | BP20: =+(F20/$N20)*100 -> 22.053478 | BQ20: =+(G20/$O20)*100 -> 45.252512 | BR20: =+(H20/$N20)*100 -> 24.70314 | BS20: =+(I20/$O20)*100 -> 13.98041 | BT20: =+(J20/$N20)*100 -> 0 | BU20: =+(K20/$O20)*100 -> 0 | BV20: ND | BW20: ND | BX20: =+(N20/$N20)*100 -> 100 | BY20: =+(O20/$O20)*100 -> 100 | BZ20: ND | CA20: ND
A21: 35186 | B21: =+'[1]Senda Inflación Total'!F505 -> 19.78 | C21: =+'[1]Senda Inflación Total'!D505 -> 24.58 | D21: 17694.366 | E21: 924.85888 | F21: 7198.3922 | G21: 983.24602 | H21: 8290.727 | I21: 322.63806 | L21: =+H21 -> 8290.727 | M21: =+I21 -> 322.63806 | N21: =+D21+F21+H21+J21 -> 33183.485 | O21: =+E21+G21+I21+K21 -> 2230.743 | P21: =+L21+J21+F21+D21 -> 33183.485 | Q21: =+M21+K21+G21+E21 -> 2230.743 | R21: =+D21+F21+L21 -> 33183.485 | S21: =+E21+G21+M21 -> 2230.743 | V21: =+D21/D9*100-100 -> 38.202591 | W21: =+E21/E9*100-100 -> 73.278769 | X21: =+F21/F9*100-100 -> 18.450512 | Y21: =+G21/G9*100-100 -> 36.035362 | Z21: =+H21/H9*100-100 -> 36.875143 | AA21: =+I21/I9*100-100 -> 61.429674 | AD21: =+L21/L9*100-100 -> 36.875143 | AE21: =+M21/M9*100-100 -> 61.429674 | AF21: =+N21/N9*100-100 -> 33.066688 | AG21: =+O21/O9*100-100 -> 53.169293 | AH21: =+P21/P9*100-100 -> 33.066688 | AI21: =+Q21/Q9*100-100 -> 53.169293 | AJ21: =+R21/R9*100-100 -> 33.066688 | AK21: =+S21/S9*100-100 -> 53.169293 | AN21: =+(1+V21/100)/(1+$B21/100)*100-100 -> 15.380357 | AO21: =+(1+W21/100)/(1+$B21/100)*100-100 -> 44.664192 | AP21: =+(1+X21/100)/(1+$B21/100)*100-100 -> -1.1099419 | AQ21: =+(1+Y21/100)/(1+$B21/100)*100-100 -> 13.571015 | AR21: =+(1+Z21/100)/(1+$B21/100)*100-100 -> 14.272118 | AS21: =+(1+AA21/100)/(1+$B21/100)*100-100 -> 34.77181 | AT21: =+(1+AB21/100)/(1+$B21/100)*100-100 -> -16.513608 | AU21: =+(1+AC21/100)/(1+$B21/100)*100-100 -> -16.513608 | ... BC21: =+(1+AK21/100)/(1+$B21/100)*100-100 -> 27.875516 | BF21: =+(E21/D21)*100 -> 5.2268552 | BG21: =+(G21/F21)*100 -> 13.659245 | BH21: =+(I21/H21)*100 -> 3.8915533 | BI21: =+(K21/J21)*100 -> #DIV/0! | BJ21: =+(M21/L21)*100 -> 3.8915533 | BK21: =+(O21/N21)*100 -> 6.7224493 | BL21: =+(Q21/P21)*100 -> 6.7224493 | BM21: =+(S21/R21)*100 -> 6.7224493 | BN21: =+(D21/$N21)*100 -> 53.322808 | BO21: =+(E21/$O21)*100 -> 41.459679 | BP21: =+(F21/$N21)*100 -> 21.692695 | BQ21: =+(G21/$O21)*100 -> 44.077065 | BR21: =+(H21/$N21)*100 -> 24.984497 | BS21: =+(I21/$O21)*100 -> 14.463256 | BT21: =+(J21/$N21)*100 -> 0 | BU21: =+(K21/$O21)*100 -> 0 | BV21: ND | BW21: ND | BX21: =+(N21/$N21)*100 -> 100 | BY21: =+(O21/$O21)*100 -> 100 | BZ21: ND | CA21: ND
A22: 35217 | B22: =+'[1]Senda Inflación Total'!F506 -> 19.7 | C22: =+'[1]Senda Inflación Total'!D506 -> 24.87 | D22: 17981.851 | E22: 903.9397 | F22: 7227.9786 | G22: 988.03819 | H22: 8528.1092 | I22: 336.47764 | L22: =+H22 -> 8528.1092 | M22: =+I22 -> 336.47764 | N22: =+D22+F22+H22+J22 -> 33737.939 | O22: =+E22+G22+I22+K22 -> 2228.4555 | P22: =+L22+J22+F22+D22 -> 33737.939 | Q22: =+M22+K22+G22+E22 -> 2228.4555 | R22: =+D22+F22+L22 -> 33737.939 | S22: =+E22+G22+M22 -> 2228.4555 | V22: =+D22/D10*100-100 -> 35.904089 | W22: =+E22/E10*100-100 -> 70.835178 | X22: =+F22/F10*100-100 -> 17.699774 | Y22: =+G22/G10*100-100 -> 41.32163 | Z22: =+H22/H10*100-100 -> 36.866281 | AA22: =+I22/I10*100-100 -> 54.812426 | AD22: =+L22/L10*100-100 -> 36.866281 | AE22: =+M22/M10*100-100 -> 54.812426 | AF22: =+N22/N10*100-100 -> 31.771892 | AG22: =+O22/O10*100-100 -> 54.152596 | AH22: =+P22/P10*100-100 -> 31.771892 | AI22: =+Q22/Q10*100-100 -> 54.152596 | AJ22: =+R22/R10*100-100 -> 31.771892 | AK22: =+S22/S10*100-100 -> 54.152596 | AN22: =+(1+V22/100)/(1+$B22/100)*100-100 -> 13.537251 | AO22: =+(1+W22/100)/(1+$B22/100)*100-100 -> 42.719447 | AP22: =+(1+X22/100)/(1+$B22/100)*100-100 -> -1.6710325 | AQ22: =+(1+Y22/100)/(1+$B22/100)*100-100 -> 18.063183 | AR22: =+(1+Z22/100)/(1+$B22/100)*100-100 -> 14.341087 | AS22: =+(1+AA22/100)/(1+$B22/100)*100-100 -> 29.333689 | AT22: =+(1+AB22/100)/(1+$B22/100)*100-100 -> -16.457811 | AU22: =+(1+AC22/100)/(1+$B22/100)*100-100 -> -16.457811 | ... BC22: =+(1+AK22/100)/(1+$B22/100)*100-100 -> 28.782453 | BF22: =+(E22/D22)*100 -> 5.0269557 | BG22: =+(G22/F22)*100 -> 13.669634 | BH22: =+(I22/H22)*100 -> 3.9455128 | BI22: =+(K22/J22)*100 -> #DIV/0! | BJ22: =+(M22/L22)*100 -> 3.9455128 | BK22: =+(O22/N22)*100 -> 6.6051916 | BL22: =+(Q22/P22)*100 -> 6.6051916 | BM22: =+(S22/R22)*100 -> 6.6051916 | BN22: =+(D22/$N22)*100 -> 53.298606 | BO22: =+(E22/$O22)*100 -> 40.563506 | BP22: =+(F22/$N22)*100 -> 21.423889 | BQ22: =+(G22/$O22)*100 -> 44.337353 | BR22: =+(H22/$N22)*100 -> 25.277505 | BS22: =+(I22/$O22)*100 -> 15.099141 | BT22: =+(J22/$N22)*100 -> 0 | BU22: =+(K22/$O22)*100 -> 0 | BV22: ND | BW22: ND | BX22: =+(N22/$N22)*100 -> 100 | BY22: =+(O22/$O22)*100 -> 100 | BZ22: ND | CA22: ND
A23: 35247 | B23: =+'[1]Senda Inflación Total'!F507 -> 20.57 | C23: =+'[1]Senda Inflación Total'!D507 -> 25.24 | D23: 18206.785 | E23: 1012.8559 | F23: 7345.5398 | G23: 1018.5946 | H23: 8788.178 | I23: 350.67155 | L23: =+H23 -> 8788.178 | M23: =+I23 -> 350.67155 | N23: =+D23+F23+H23+J23 -> 34340.502 | O23: =+E23+G23+I23+K23 -> 2382.1221 | P23: =+L23+J23+F23+D23 -> 34340.502 | Q23: =+M23+K23+G23+E23 -> 2382.1221 | R23: =+D23+F23+L23 -> 34340.502 | S23: =+E23+G23+M23 -> 2382.1221 | V23: =+D23/D11*100-100 -> 32.504965 | W23: =+E23/E11*100-100 -> 57.938046 | X23: =+F23/F11*100-100 -> 17.952481 | Y23: =+G23/G11*100-100 -> 30.46784 | Z23: =+H23/H11*100-100 -> 40.123834 | AA23: =+I23/I11*100-100 -> 64.960463 | AD23: =+L23/L11*100-100 -> 40.123834 | AE23: =+M23/M11*100-100 -> 64.960463 | AF23: =+N23/N11*100-100 -> 30.87222 | AG23: =+O23/O11*100-100 -> 45.730896 | AH23: =+P23/P11*100-100 -> 30.87222 | AI23: =+Q23/Q11*100-100 -> 45.730896 | AJ23: =+R23/R11*100-100 -> 30.87222 | AK23: =+S23/S11*100-100 -> 45.730896 | AN23: =+(1+V23/100)/(1+$B23/100)*100-100 -> 9.8987853 | AO23: =+(1+W23/100)/(1+$B23/100)*100-100 -> 30.992822 | AP23: =+(1+X23/100)/(1+$B23/100)*100-100 -> -2.1709536 | AQ23: =+(1+Y23/100)/(1+$B23/100)*100-100 -> 8.2092062 | AR23: =+(1+Z23/100)/(1+$B23/100)*100-100 -> 16.217827 | AS23: =+(1+AA23/100)/(1+$B23/100)*100-100 -> 36.817171 | AT23: =+(1+AB23/100)/(1+$B23/100)*100-100 -> -17.060629 | AU23: =+(1+AC23/100)/(1+$B23/100)*100-100 -> -17.060629 | ... BC23: =+(1+AK23/100)/(1+$B23/100)*100-100 -> 20.868289 | BF23: =+(E23/D23)*100 -> 5.5630686 | BG23: =+(G23/F23)*100 -> 13.866845 | BH23: =+(I23/H23)*100 -> 3.9902646 | BI23: =+(K23/J23)*100 -> #DIV/0! | BJ23: =+(M23/L23)*100 -> 3.9902646 | BK23: =+(O23/N23)*100 -> 6.9367712 | BL23: =+(Q23/P23)*100 -> 6.9367712 | BM23: =+(S23/R23)*100 -> 6.9367712 | BN23: =+(D23/$N23)*100 -> 53.018399 | BO23: =+(E23/$O23)*100 -> 42.519061 | BP23: =+(F23/$N23)*100 -> 21.39031 | BQ23: =+(G23/$O23)*100 -> 42.759966 | BR23: =+(H23/$N23)*100 -> 25.591291 | BS23: =+(I23/$O23)*100 -> 14.720973 | BT23: =+(J23/$N23)*100 -> 0 | BU23: =+(K23/$O23)*100 -> 0 | BV23: ND | BW23: ND | BX23: =+(N23/$N23)*100 -> 100 | BY23: =+(O23/$O23)*100 -> 100 | BZ23: ND | CA23: ND
A24: 35278 | B24: =+'[1]Senda Inflación Total'!F508 -> 21.13 | C24: =+'[1]Senda Inflación Total'!D508 -> 25.52 | D24: 18426.464 | E24: 1104.8916 | F24: 7418.3198 | G24: 1047.7519 | H24: 9041.3167 | I24: 364.25691 | L24: =+H24 -> 9041.3167 | M24: =+I24 -> 364.25691 | N24: =+D24+F24+H24+J24 -> 34886.1 | O24: =+E24+G24+I24+K24 -> 2516.9004 | P24: =+L24+J24+F24+D24 -> 34886.1 | Q24: =+M24+K24+G24+E24 -> 2516.9004 | R24: =+D24+F24+L24 -> 34886.1 | S24: =+E24+G24+M24 -> 2516.9004 | V24: =+D24/D12*100-100 -> 29.335976 | W24: =+E24/E12*100-100 -> 66.774375 | X24: =+F24/F12*100-100 -> 17.271854 | Y24: =+G24/G12*100-100 -> 33.312388 | Z24: =+H24/H12*100-100 -> 39.16213 | AA24: =+I24/I12*100-100 -> 62.123848 | AD24: =+L24/L12*100-100 -> 39.16213 | AE24: =+M24/M12*100-100 -> 62.123848 | AF24: =+N24/N12*100-100 -> 28.875151 | AG24: =+O24/O12*100-100 -> 50.431339 | AH24: =+P24/P12*100-100 -> 28.875151 | AI24: =+Q24/Q12*100-100 -> 50.431339 | AJ24: =+R24/R12*100-100 -> 28.875151 | AK24: =+S24/S12*100-100 -> 50.431339 | AN24: =+(1+V24/100)/(1+$B24/100)*100-100 -> 6.7745197 | AO24: =+(1+W24/100)/(1+$B24/100)*100-100 -> 37.682139 | AP24: =+(1+X24/100)/(1+$B24/100)*100-100 -> -3.1851283 | AQ24: =+(1+Y24/100)/(1+$B24/100)*100-100 -> 10.057284 | AR24: =+(1+Z24/100)/(1+$B24/100)*100-100 -> 14.886593 | AS24: =+(1+AA24/100)/(1+$B24/100)*100-100 -> 33.842853 | AT24: =+(1+AB24/100)/(1+$B24/100)*100-100 -> -17.444068 | AU24: =+(1+AC24/100)/(1+$B24/100)*100-100 -> -17.444068 | ... BC24: =+(1+AK24/100)/(1+$B24/100)*100-100 -> 24.189993 | BF24: =+(E24/D24)*100 -> 5.9962215 | BG24: =+(G24/F24)*100 -> 14.123844 | BH24: =+(I24/H24)*100 -> 4.0288038 | BI24: =+(K24/J24)*100 -> #DIV/0! | BJ24: =+(M24/L24)*100 -> 4.0288038 | BK24: =+(O24/N24)*100 -> 7.2146224 | BL24: =+(Q24/P24)*100 -> 7.2146224 | BM24: =+(S24/R24)*100 -> 7.2146224 | BN24: =+(D24/$N24)*100 -> 52.818927 | BO24: =+(E24/$O24)*100 -> 43.8989 | BP24: =+(F24/$N24)*100 -> 21.2644 | BQ24: =+(G24/$O24)*100 -> 41.62866 | BR24: =+(H24/$N24)*100 -> 25.916673 | BS24: =+(I24/$O24)*100 -> 14.47244 | BT24: =+(J24/$N24)*100 -> 0 | BU24: =+(K24/$O24)*100 -> 0 | BV24: ND | BW24: ND | BX24: =+(N24/$N24)*100 -> 100 | BY24: =+(O24/$O24)*100 -> 100 | BZ24: ND | CA24: ND
A25: 35309 | B25: =+'[1]Senda Inflación Total'!F509 -> 21.55 | C25: =+'[1]Senda Inflación Total'!D509 -> 25.82 | D25: 18703.253 | E25: 1088.7846 | F25: 7505.357 | G25: 1063.2052 | H25: 9286.2702 | I25: 389.61253 | L25: =+H25 -> 9286.2702 | M25: =+I25 -> 389.61253 | N25: =+D25+F25+H25+J25 -> 35494.881 | O25: =+E25+G25+I25+K25 -> 2541.6024 | P25: =+L25+J25+F25+D25 -> 35494.881 | Q25: =+M25+K25+G25+E25 -> 2541.6024 | R25: =+D25+F25+L25 -> 35494.881 | S25: =+E25+G25+M25 -> 2541.6024 | V25: =+D25/D13*100-100 -> 26.685541 | W25: =+E25/E13*100-100 -> 67.512702 | X25: =+F25/F13*100-100 -> 15.958866 | Y25: =+G25/G13*100-100 -> 36.441807 | Z25: =+H25/H13*100-100 -> 38.861733 | AA25: =+I25/I13*100-100 -> 71.097491 | AD25: =+L25/L13*100-100 -> 38.861733 | AE25: =+M25/M13*100-100 -> 71.097491 | AF25: =+N25/N13*100-100 -> 27.115277 | AG25: =+O25/O13*100-100 -> 53.392976 | AH25: =+P25/P13*100-100 -> 27.115277 | AI25: =+Q25/Q13*100-100 -> 53.392976 | AJ25: =+R25/R13*100-100 -> 27.115277 | AK25: =+S25/S13*100-100 -> 53.392976 | AN25: =+(1+V25/100)/(1+$B25/100)*100-100 -> 4.2250441 | AO25: =+(1+W25/100)/(1+$B25/100)*100-100 -> 37.813823 | AP25: =+(1+X25/100)/(1+$B25/100)*100-100 -> -4.5998635 | AQ25: =+(1+Y25/100)/(1+$B25/100)*100-100 -> 12.251589 | AR25: =+(1+Z25/100)/(1+$B25/100)*100-100 -> 14.242479 | AS25: =+(1+AA25/100)/(1+$B25/100)*100-100 -> 40.763053 | AT25: =+(1+AB25/100)/(1+$B25/100)*100-100 -> -17.729329 | AU25: =+(1+AC25/100)/(1+$B25/100)*100-100 -> -17.729329 | ... BC25: =+(1+AK25/100)/(1+$B25/100)*100-100 -> 26.19743 | BF25: =+(E25/D25)*100 -> 5.821365 | BG25: =+(G25/F25)*100 -> 14.165951 | BH25: =+(I25/H25)*100 -> 4.1955761 | BI25: =+(K25/J25)*100 -> #DIV/0! | BJ25: =+(M25/L25)*100 -> 4.1955761 | BK25: =+(O25/N25)*100 -> 7.1604759 | BL25: =+(Q25/P25)*100 -> 7.1604759 | BM25: =+(S25/R25)*100 -> 7.1604759 | BN25: =+(D25/$N25)*100 -> 52.69282 | BO25: =+(E25/$O25)*100 -> 42.838512 | BP25: =+(F25/$N25)*100 -> 21.1449 | BQ25: =+(G25/$O25)*100 -> 41.832082 | BR25: =+(H25/$N25)*100 -> 26.16228 | BS25: =+(I25/$O25)*100 -> 15.329405 | BT25: =+(J25/$N25)*100 -> 0 | BU25: =+(K25/$O25)*100 -> 0 | BV25: ND | BW25: ND | BX25: =+(N25/$N25)*100 -> 100 | BY25: =+(O25/$O25)*100 -> 100 | BZ25: ND | CA25: ND
A26: 35339 | B26: =+'[1]Senda Inflación Total'!F510 -> 21.87 | C26: =+'[1]Senda Inflación Total'!D510 -> 26.12 | D26: 18828.63 | E26: 1191.372 | F26: 7496.002 | G26: 1087.5661 | H26: 9476.0938 | I26: 410.04506 | L26: =+H26 -> 9476.0938 | M26: =+I26 -> 410.04506 | N26: =+D26+F26+H26+J26 -> 35800.726 | O26: =+E26+G26+I26+K26 -> 2688.9831 | P26: =+L26+J26+F26+D26 -> 35800.726 | Q26: =+M26+K26+G26+E26 -> 2688.9831 | R26: =+D26+F26+L26 -> 35800.726 | S26: =+E26+G26+M26 -> 2688.9831 | V26: =+D26/D14*100-100 -> 24.185409 | W26: =+E26/E14*100-100 -> 69.346671 | X26: =+F26/F14*100-100 -> 13.723566 | Y26: =+G26/G14*100-100 -> 36.336183 | Z26: =+H26/H14*100-100 -> 37.423627 | AA26: =+I26/I14*100-100 -> 73.28369 | AD26: =+L26/L14*100-100 -> 37.423627 | AE26: =+M26/M14*100-100 -> 73.28369 | AF26: =+N26/N14*100-100 -> 24.964718 | AG26: =+O26/O14*100-100 -> 54.730271 | AH26: =+P26/P14*100-100 -> 24.964718 | AI26: =+Q26/Q14*100-100 -> 54.730271 | AJ26: =+R26/R14*100-100 -> 24.964718 | AK26: =+S26/S14*100-100 -> 54.730271 | AN26: =+(1+V26/100)/(1+$B26/100)*100-100 -> 1.8999006 | AO26: =+(1+W26/100)/(1+$B26/100)*100-100 -> 38.956816 | AP26: =+(1+X26/100)/(1+$B26/100)*100-100 -> -6.6845276 | AQ26: =+(1+Y26/100)/(1+$B26/100)*100-100 -> 11.870176 | AR26: =+(1+Z26/100)/(1+$B26/100)*100-100 -> 12.762474 | AS26: =+(1+AA26/100)/(1+$B26/100)*100-100 -> 42.187323 | AT26: =+(1+AB26/100)/(1+$B26/100)*100-100 -> -17.945352 | AU26: =+(1+AC26/100)/(1+$B26/100)*100-100 -> -17.945352 | ... BC26: =+(1+AK26/100)/(1+$B26/100)*100-100 -> 26.96338 | BF26: =+(E26/D26)*100 -> 6.3274489 | BG26: =+(G26/F26)*100 -> 14.508615 | BH26: =+(I26/H26)*100 -> 4.3271528 | BI26: =+(K26/J26)*100 -> #DIV/0! | BJ26: =+(M26/L26)*100 -> 4.3271528 | BK26: =+(O26/N26)*100 -> 7.5109736 | BL26: =+(Q26/P26)*100 -> 7.5109736 | BM26: =+(S26/R26)*100 -> 7.5109736 | BN26: =+(D26/$N26)*100 -> 52.592873 | BO26: =+(E26/$O26)*100 -> 44.30567 | BP26: =+(F26/$N26)*100 -> 20.938128 | BQ26: =+(G26/$O26)*100 -> 40.445255 | BR26: =+(H26/$N26)*100 -> 26.468999 | BS26: =+(I26/$O26)*100 -> 15.249075 | BT26: =+(J26/$N26)*100 -> 0 | BU26: =+(K26/$O26)*100 -> 0 | BV26: ND | BW26: ND | BX26: =+(N26/$N26)*100 -> 100 | BY26: =+(O26/$O26)*100 -> 100 | BZ26: ND | CA26: ND
A27: 35370 | B27: =+'[1]Senda Inflación Total'!F511 -> 21.88 | C27: =+'[1]Senda Inflación Total'!D511 -> 26.33 | D27: 19485.43 | E27: 1253.6855 | F27: 7385.9305 | G27: 1100.2679 | H27: 9731.0553 | I27: 444.00469 | L27: =+H27 -> 9731.0553 | M27: =+I27 -> 444.00469 | N27: =+D27+F27+H27+J27 -> 36602.415 | O27: =+E27+G27+I27+K27 -> 2797.9581 | P27: =+L27+J27+F27+D27 -> 36602.415 | Q27: =+M27+K27+G27+E27 -> 2797.9582 | R27: =+D27+F27+L27 -> 36602.415 | S27: =+E27+G27+M27 -> 2797.9581 | V27: =+D27/D15*100-100 -> 24.559313 | W27: =+E27/E15*100-100 -> 72.92194 | X27: =+F27/F15*100-100 -> 10.391502 | Y27: =+G27/G15*100-100 -> 32.779832 | Z27: =+H27/H15*100-100 -> 38.034073 | AA27: =+I27/I15*100-100 -> 77.021402 | AD27: =+L27/L15*100-100 -> 38.034073 | AE27: =+M27/M15*100-100 -> 77.021402 | AF27: =+N27/N15*100-100 -> 24.566172 | AG27: =+O27/O15*100-100 -> 55.057793 | AH27: =+P27/P15*100-100 -> 24.566172 | AI27: =+Q27/Q15*100-100 -> 55.057793 | AJ27: =+R27/R15*100-100 -> 24.566172 | AK27: =+S27/S15*100-100 -> 55.057793 | AN27: =+(1+V27/100)/(1+$B27/100)*100-100 -> 2.1983206 | AO27: =+(1+W27/100)/(1+$B27/100)*100-100 -> 41.878848 | AP27: =+(1+X27/100)/(1+$B27/100)*100-100 -> -9.4260732 | AQ27: =+(1+Y27/100)/(1+$B27/100)*100-100 -> 8.9430848 | AR27: =+(1+Z27/100)/(1+$B27/100)*100-100 -> 13.25408 | AS27: =+(1+AA27/100)/(1+$B27/100)*100-100 -> 45.242371 | AT27: =+(1+AB27/100)/(1+$B27/100)*100-100 -> -17.952084 | AU27: =+(1+AC27/100)/(1+$B27/100)*100-100 -> -17.952084 | ... BC27: =+(1+AK27/100)/(1+$B27/100)*100-100 -> 27.221688 | BF27: =+(E27/D27)*100 -> 6.433964 | BG27: =+(G27/F27)*100 -> 14.896809 | BH27: =+(I27/H27)*100 -> 4.5627599 | BI27: =+(K27/J27)*100 -> #DIV/0! | BJ27: =+(M27/L27)*100 -> 4.5627599 | BK27: =+(O27/N27)*100 -> 7.6441899 | BL27: =+(Q27/P27)*100 -> 7.6441899 | BM27: =+(S27/R27)*100 -> 7.6441899 | BN27: =+(D27/$N27)*100 -> 53.235365 | BO27: =+(E27/$O27)*100 -> 44.807158 | BP27: =+(F27/$N27)*100 -> 20.178806 | BQ27: =+(G27/$O27)*100 -> 39.32396 | BR27: =+(H27/$N27)*100 -> 26.585828 | BS27: =+(I27/$O27)*100 -> 15.868882 | BT27: =+(J27/$N27)*100 -> 0 | BU27: =+(K27/$O27)*100 -> 0 | BV27: ND | BW27: ND | BX27: =+(N27/$N27)*100 -> 100 | BY27: =+(O27/$O27)*100 -> 100 | BZ27: ND | CA27: ND
A28: 35400 | B28: =+'[1]Senda Inflación Total'!F512 -> 21.63 | C28: =+'[1]Senda Inflación Total'!D512 -> 26.52 | D28: 20911.691 | E28: 1187.6357 | F28: ='[2]Dic-96'!$D$617/1000 -> 6781.9526 | G28: 879.57236 | H28: ='[2]Dic-96'!$D$630/1000 -> 9977.0954 | I28: ='[2]Dic-96'!$D$631/1000 -> 468.36723 | L28: =+H28 -> 9977.0954 | M28: =+I28 -> 468.36723 | N28: =+D28+F28+H28+J28 -> 37670.739 | O28: =+E28+G28+I28+K28 -> 2535.5753 | P28: =+L28+J28+F28+D28 -> 37670.739 | Q28: =+M28+K28+G28+E28 -> 2535.5753 | R28: =+D28+F28+L28 -> 37670.739 | S28: =+E28+G28+M28 -> 2535.5753 | V28: =+D28/D16*100-100 -> 30.034412 | W28: =+E28/E16*100-100 -> 80.840333 | X28: =+F28/F16*100-100 -> 0.69517273 | Y28: =+G28/G16*100-100 -> 7.1036304 | Z28: =+H28/H16*100-100 -> 37.327553 | AA28: =+I28/I16*100-100 -> 86.508039 | AD28: =+L28/L16*100-100 -> 37.327553 | AE28: =+M28/M16*100-100 -> 86.508039 | AF28: =+N28/N16*100-100 -> 25.22696 | AG28: =+O28/O16*100-100 -> 46.642102 | AH28: =+P28/P16*100-100 -> 25.22696 | AI28: =+Q28/Q16*100-100 -> 46.642102 | AJ28: =+R28/R16*100-100 -> 25.22696 | AK28: =+S28/S16*100-100 -> 46.642102 | AN28: =+(1+V28/100)/(1+$B28/100)*100-100 -> 6.9098183 | AO28: =+(1+W28/100)/(1+$B28/100)*100-100 -> 48.680698 | AP28: =+(1+X28/100)/(1+$B28/100)*100-100 -> -17.211894 | AQ28: =+(1+Y28/100)/(1+$B28/100)*100-100 -> -11.943081 | AR28: =+(1+Z28/100)/(1+$B28/100)*100-100 -> 12.905988 | AS28: =+(1+AA28/100)/(1+$B28/100)*100-100 -> 53.34049 | AT28: =+(1+AB28/100)/(1+$B28/100)*100-100 -> -17.783442 | AU28: =+(1+AC28/100)/(1+$B28/100)*100-100 -> -17.783442 | ... BC28: =+(1+AK28/100)/(1+$B28/100)*100-100 -> 20.564089 | BF28: =+(E28/D28)*100 -> 5.6792906 | BG28: =+(G28/F28)*100 -> 12.969309 | BH28: =+(I28/H28)*100 -> 4.6944247 | BI28: =+(K28/J28)*100 -> #DIV/0! | BJ28: =+(M28/L28)*100 -> 4.6944247 | BK28: =+(O28/N28)*100 -> 6.7308881 | BL28: =+(Q28/P28)*100 -> 6.7308881 | BM28: =+(S28/R28)*100 -> 6.7308881 | BN28: =+(D28/$N28)*100 -> 55.511762 | BO28: =+(E28/$O28)*100 -> 46.838905 | BP28: =+(F28/$N28)*100 -> 18.003237 | BQ28: =+(G28/$O28)*100 -> 34.689262 | BR28: =+(H28/$N28)*100 -> 26.485 | BS28: =+(I28/$O28)*100 -> 18.471833 | BT28: =+(J28/$N28)*100 -> 0 | BU28: =+(K28/$O28)*100 -> 0 | BV28: ND | BW28: ND | BX28: =+(N28/$N28)*100 -> 100 | BY28: =+(O28/$O28)*100 -> 100 | BZ28: ND | CA28: ND
A29: 35431 | B29: =+'[1]Senda Inflación Total'!F513 -> 20.62 | C29: =+'[1]Senda Inflación Total'!D513 -> 26.96 | D29: 21077.016 | E29: 1370.1327 | F29: 6988.0018 | G29: ='[2]Dic-96'!$E$618/1000 -> 879.57231 | H29: 10203.729 | I29: 507.85287 | L29: =+H29 -> 10203.729 | M29: =+I29 -> 507.85287 | N29: =+D29+F29+H29+J29 -> 38268.747 | O29: =+E29+G29+I29+K29 -> 2757.5579 | P29: =+L29+J29+F29+D29 -> 38268.747 | Q29: =+M29+K29+G29+E29 -> 2757.5579 | R29: =+D29+F29+L29 -> 38268.747 | S29: =+E29+G29+M29 -> 2757.5579 | V29: =+D29/D17*100-100 -> 28.74712 | W29: =+E29/E17*100-100 -> 80.444003 | X29: =+F29/F17*100-100 -> 1.3877294 | Y29: =+G29/G17*100-100 -> -0.47261494 | Z29: =+H29/H17*100-100 -> 36.608611 | AA29: =+I29/I17*100-100 -> 83.676275 | AD29: =+L29/L17*100-100 -> 36.608611 | AE29: =+M29/M17*100-100 -> 83.676275 | AF29: =+N29/N17*100-100 -> 24.521935 | AG29: =+O29/O17*100-100 -> 43.656151 | AH29: =+P29/P17*100-100 -> 24.521935 | AI29: =+Q29/Q17*100-100 -> 43.656151 | AJ29: =+R29/R17*100-100 -> 24.521935 | AK29: =+S29/S17*100-100 -> 43.656151 | AN29: =+(1+V29/100)/(1+$B29/100)*100-100 -> 6.7377882 | AO29: =+(1+W29/100)/(1+$B29/100)*100-100 -> 49.597084 | AP29: =+(1+X29/100)/(1+$B29/100)*100-100 -> -15.944512 | AQ29: =+(1+Y29/100)/(1+$B29/100)*100-100 -> -17.48683 | AR29: =+(1+Z29/100)/(1+$B29/100)*100-100 -> 13.255357 | AS29: =+(1+AA29/100)/(1+$B29/100)*100-100 -> 52.276799 | AT29: =+(1+AB29/100)/(1+$B29/100)*100-100 -> -17.095009 | AU29: =+(1+AC29/100)/(1+$B29/100)*100-100 -> -17.095009 | ... BC29: =+(1+AK29/100)/(1+$B29/100)*100-100 -> 19.098119 | BF29: =+(E29/D29)*100 -> 6.5006012 | BG29: =+(G29/F29)*100 -> 12.586893 | BH29: =+(I29/H29)*100 -> 4.9771302 | BI29: =+(K29/J29)*100 -> #DIV/0! | BJ29: =+(M29/L29)*100 -> 4.9771302 | BK29: =+(O29/N29)*100 -> 7.2057702 | BL29: =+(Q29/P29)*100 -> 7.2057702 | BM29: =+(S29/R29)*100 -> 7.2057702 | BN29: =+(D29/$N29)*100 -> 55.076316 | BO29: =+(E29/$O29)*100 -> 49.686454 | BP29: =+(F29/$N29)*100 -> 18.260336 | BQ29: =+(G29/$O29)*100 -> 31.896784 | BR29: =+(H29/$N29)*100 -> 26.663347 | BS29: =+(I29/$O29)*100 -> 18.416762 | BT29: =+(J29/$N29)*100 -> 0 | BU29: =+(K29/$O29)*100 -> 0 | BV29: ND | BW29: ND | BX29: =+(N29/$N29)*100 -> 100 | BY29: =+(O29/$O29)*100 -> 100 | BZ29: ND | CA29: ND
A30: 35462 | B30: =+'[1]Senda Inflación Total'!F514 -> 19.58 | C30: =+'[1]Senda Inflación Total'!D514 -> 27.8 | D30: 21385.497 | E30: 1380.4963 | F30: 7165.5649 | G30: 977.65909 | H30: 10418.016 | I30: 534.6808 | L30: =+H30 -> 10418.016 | M30: =+I30 -> 534.6808 | N30: =+D30+F30+H30+J30 -> 38969.078 | O30: =+E30+G30+I30+K30 -> 2892.8362 | P30: =+L30+J30+F30+D30 -> 38969.078 | Q30: =+M30+K30+G30+E30 -> 2892.8362 | R30: =+D30+F30+L30 -> 38969.078 | S30: =+E30+G30+M30 -> 2892.8362 | V30: =+D30/D18*100-100 -> 28.604932 | W30: =+E30/E18*100-100 -> 71.228785 | X30: =+F30/F18*100-100 -> 2.6021245 | Y30: =+G30/G18*100-100 -> 5.1521696 | Z30: =+H30/H18*100-100 -> 36.181982 | AA30: =+I30/I18*100-100 -> 88.96979 | AD30: =+L30/L18*100-100 -> 36.181982 | AE30: =+M30/M18*100-100 -> 88.96979 | AF30: =+N30/N18*100-100 -> 24.650243 | AG30: =+O30/O18*100-100 -> 43.285562 | AH30: =+P30/P18*100-100 -> 24.650243 | AI30: =+Q30/Q18*100-100 -> 43.285562 | AJ30: =+R30/R18*100-100 -> 24.650243 | AK30: =+S30/S18*100-100 -> 43.285562 | AN30: =+(1+V30/100)/(1+$B30/100)*100-100 -> 7.547192 | AO30: =+(1+W30/100)/(1+$B30/100)*100-100 -> 43.191825 | AP30: =+(1+X30/100)/(1+$B30/100)*100-100 -> -14.197922 | AQ30: =+(1+Y30/100)/(1+$B30/100)*100-100 -> -12.065421 | AR30: =+(1+Z30/100)/(1+$B30/100)*100-100 -> 13.883578 | AS30: =+(1+AA30/100)/(1+$B30/100)*100-100 -> 58.027923 | AT30: =+(1+AB30/100)/(1+$B30/100)*100-100 -> -16.373976 | AU30: =+(1+AC30/100)/(1+$B30/100)*100-100 -> -16.373976 | ... BC30: =+(1+AK30/100)/(1+$B30/100)*100-100 -> 19.824019 | BF30: =+(E30/D30)*100 -> 6.455292 | BG30: =+(G30/F30)*100 -> 13.643852 | BH30: =+(I30/H30)*100 -> 5.1322711 | BI30: =+(K30/J30)*100 -> #DIV/0! | BJ30: =+(M30/L30)*100 -> 5.1322711 | BK30: =+(O30/N30)*100 -> 7.4234145 | BL30: =+(Q30/P30)*100 -> 7.4234145 | BM30: =+(S30/R30)*100 -> 7.4234145 | BN30: =+(D30/$N30)*100 -> 54.87812 | BO30: =+(E30/$O30)*100 -> 47.721205 | BP30: =+(F30/$N30)*100 -> 18.387823 | BQ30: =+(G30/$O30)*100 -> 33.795868 | BR30: =+(H30/$N30)*100 -> 26.734057 | BS30: =+(I30/$O30)*100 -> 18.482927 | BT30: =+(J30/$N30)*100 -> 0 | BU30: =+(K30/$O30)*100 -> 0 | BV30: ND | BW30: ND | BX30: =+(N30/$N30)*100 -> 100 | BY30: =+(O30/$O30)*100 -> 100 | BZ30: ND | CA30: ND
A31: 35490 | B31: =+'[1]Senda Inflación Total'!F515 -> 18.93 | C31: =+'[1]Senda Inflación Total'!D515 -> 28.23 | D31: 21589.979 | E31: 1396.0562 | F31: 7285.6969 | G31: 1053.6412 | H31: 10652.597 | I31: 570.19793 | L31: =+H31 -> 10652.597 | M31: =+I31 -> 570.19793 | N31: =+D31+F31+H31+J31 -> 39528.273 | O31: =+E31+G31+I31+K31 -> 3019.8953 | P31: =+L31+J31+F31+D31 -> 39528.273 | Q31: =+M31+K31+G31+E31 -> 3019.8953 | R31: =+D31+F31+L31 -> 39528.273 | S31: =+E31+G31+M31 -> 3019.8953 | V31: =+D31/D19*100-100 -> 26.505703 | W31: =+E31/E19*100-100 -> 72.528978 | X31: =+F31/F19*100-100 -> 3.0672154 | Y31: =+G31/G19*100-100 -> 11.270403 | Z31: =+H31/H19*100-100 -> 35.61854 | AA31: =+I31/I19*100-100 -> 95.252254 | AD31: =+L31/L19*100-100 -> 35.61854 | AE31: =+M31/M19*100-100 -> 95.252254 | AF31: =+N31/N19*100-100 -> 23.56404 | AG31: =+O31/O19*100-100 -> 47.446973 | AH31: =+P31/P19*100-100 -> 23.56404 | AI31: =+Q31/Q19*100-100 -> 47.446973 | AJ31: =+R31/R19*100-100 -> 23.56404 | AK31: =+S31/S19*100-100 -> 47.446973 | AN31: =+(1+V31/100)/(1+$B31/100)*100-100 -> 6.3698839 | AO31: =+(1+W31/100)/(1+$B31/100)*100-100 -> 45.067669 | AP31: =+(1+X31/100)/(1+$B31/100)*100-100 -> -13.337917 | AQ31: =+(1+Y31/100)/(1+$B31/100)*100-100 -> -6.4404246 | AR31: =+(1+Z31/100)/(1+$B31/100)*100-100 -> 14.032237 | AS31: =+(1+AA31/100)/(1+$B31/100)*100-100 -> 64.174097 | AT31: =+(1+AB31/100)/(1+$B31/100)*100-100 -> -15.916926 | AU31: =+(1+AC31/100)/(1+$B31/100)*100-100 -> -15.916926 | ... BC31: =+(1+AK31/100)/(1+$B31/100)*100-100 -> 23.977947 | BF31: =+(E31/D31)*100 -> 6.4662231 | BG31: =+(G31/F31)*100 -> 14.461776 | BH31: =+(I31/H31)*100 -> 5.3526658 | BI31: =+(K31/J31)*100 -> #DIV/0! | BJ31: =+(M31/L31)*100 -> 5.3526658 | BK31: =+(O31/N31)*100 -> 7.6398362 | BL31: =+(Q31/P31)*100 -> 7.6398362 | BM31: =+(S31/R31)*100 -> 7.6398362 | BN31: =+(D31/$N31)*100 -> 54.61908 | BO31: =+(E31/$O31)*100 -> 46.228629 | BP31: =+(F31/$N31)*100 -> 18.431609 | BQ31: =+(G31/$O31)*100 -> 34.88999 | BR31: =+(H31/$N31)*100 -> 26.949311 | BS31: =+(I31/$O31)*100 -> 18.88138 | BT31: =+(J31/$N31)*100 -> 0 | BU31: =+(K31/$O31)*100 -> 0 | BV31: ND | BW31: ND | BX31: =+(N31/$N31)*100 -> 100 | BY31: =+(O31/$O31)*100 -> 100 | BZ31: ND | CA31: ND
A32: 35521 | B32: =+'[1]Senda Inflación Total'!F516 -> 18.52 | C32: =+'[1]Senda Inflación Total'!D516 -> 28.69 | D32: 21734.029 | E32: 1468.6465 | F32: 7264.2352 | G32: 958.53727 | H32: 10917.107 | I32: 588.46635 | L32: =+H32 -> 10917.107 | M32: =+I32 -> 588.46635 | N32: =+D32+F32+H32+J32 -> 39915.371 | O32: =+E32+G32+I32+K32 -> 3015.6501 | P32: =+L32+J32+F32+D32 -> 39915.371 | Q32: =+M32+K32+G32+E32 -> 3015.6501 | R32: =+D32+F32+L32 -> 39915.371 | S32: =+E32+G32+M32 -> 3015.6501 | V32: =+D32/D20*100-100 -> 25.615701 | W32: =+E32/E20*100-100 -> 63.951886 | X32: =+F32/F20*100-100 -> 1.3636244 | Y32: =+G32/G20*100-100 -> -3.6004404 | Z32: =+H32/H20*100-100 -> 35.995566 | AA32: =+I32/I20*100-100 -> 91.56249 | AD32: =+L32/L20*100-100 -> 35.995566 | AE32: =+M32/M20*100-100 -> 91.56249 | AF32: =+N32/N20*100-100 -> 22.831427 | AG32: =+O32/O20*100-100 -> 37.242837 | AH32: =+P32/P20*100-100 -> 22.831427 | AI32: =+Q32/Q20*100-100 -> 37.242837 | AJ32: =+R32/R20*100-100 -> 22.831427 | AK32: =+S32/S20*100-100 -> 37.242837 | AN32: =+(1+V32/100)/(1+$B32/100)*100-100 -> 5.9869227 | AO32: =+(1+W32/100)/(1+$B32/100)*100-100 -> 38.332675 | AP32: =+(1+X32/100)/(1+$B32/100)*100-100 -> -14.475511 | AQ32: =+(1+Y32/100)/(1+$B32/100)*100-100 -> -18.663888 | AR32: =+(1+Z32/100)/(1+$B32/100)*100-100 -> 14.744824 | AS32: =+(1+AA32/100)/(1+$B32/100)*100-100 -> 61.628831 | AT32: =+(1+AB32/100)/(1+$B32/100)*100-100 -> -15.626055 | AU32: =+(1+AC32/100)/(1+$B32/100)*100-100 -> -15.626055 | ... BC32: =+(1+AK32/100)/(1+$B32/100)*100-100 -> 15.797196 | BF32: =+(E32/D32)*100 -> 6.7573598 | BG32: =+(G32/F32)*100 -> 13.195295 | BH32: =+(I32/H32)*100 -> 5.3903139 | BI32: =+(K32/J32)*100 -> #DIV/0! | BJ32: =+(M32/L32)*100 -> 5.3903139 | BK32: =+(O32/N32)*100 -> 7.5551098 | BL32: =+(Q32/P32)*100 -> 7.5551098 | BM32: =+(S32/R32)*100 -> 7.5551098 | BN32: =+(D32/$N32)*100 -> 54.450273 | BO32: =+(E32/$O32)*100 -> 48.700825 | BP32: =+(F32/$N32)*100 -> 18.199092 | BQ32: =+(G32/$O32)*100 -> 31.785427 | BR32: =+(H32/$N32)*100 -> 27.350635 | BS32: =+(I32/$O32)*100 -> 19.513748 | BT32: =+(J32/$N32)*100 -> 0 | BU32: =+(K32/$O32)*100 -> 0 | BV32: ND | BW32: ND | BX32: =+(N32/$N32)*100 -> 100 | BY32: =+(O32/$O32)*100 -> 100 | BZ32: ND | CA32: ND
